Workbook

Sheet README
A1: Week 1 — Excel & Data Cleaning: Practice Questions + Course Project
A3: Data Analyst Course — Codec Technologies
A5: This workbook completes the Week 1 practice set and the course project.
A6: Dataset: a synthetic Global-Superstore-style sales dataset (180 cleaned rows, 3 years, 2023-2025),
A7: built to match the columns needed by every task below.
A9: PRACTICE QUESTIONS (practice_set.pdf):
A10: 1. Remove duplicates / handle missing values -> see "Raw_Data" and "Cleaned_Data" tabs
A11: 2. Pivot Table: region-wise sales -> "Analysis" tab, Task 2
A12: 3. Mean, median, mode via formulas -> "Analysis" tab, Task 3
A13: 4. Conditional formatting: top 10 sales -> "Cleaned_Data" tab, Sales column (red highlight)
A14: 5. Bar chart: category-wise revenue -> "Charts" tab
A16: COURSE PROJECT (week_1_1.pdf) — Pivot Table Dashboard:
... A28: Swap in the real file on the Raw_Data tab and every formula/chart will recompute.

Sheet Raw_Data
A1: RAW DATA (as exported) — contains duplicates and missing values
A3: Order ID | B3: Order Date | C3: Customer Name | D3: Region | E3: Category | F3: Sub-Category | G3: Product Name | H3: Department | I3: Quantity | J3: Sales | K3: Discount | L3: Profit | N3: Note:
A4: ORD-1166 | B4: 2025-04-11 | C4: Rohan Mehta | D4: East | E4: Technology | F4: Machines | G4: Machines Model 131 | H4: Corporate | I4: 6 | J4: 1890.96 | K4: 0.2 | L4: 383.98 | N4: This tab mirrors the raw export: 12 duplicate rows and blanks in Customer Name / Quantity / Sales were intentionally left in place so the cleaning steps on the Cleaned_Data tab are visible.
A5: ORD-1156 | B5: 2025-11-21 | C5: Aarav Sharma | D5: South | E5: Office Supplies | F5: Binders | G5: Binders Model 101 | H5: Consumer | I5: 10 | J5: 1565.3 | K5: 0 | L5: 215.04
A6: ORD-1064 | B6: 2024-10-22 | D6: South | E6: Technology | F6: Machines | G6: Machines Model 561 | H6: Corporate | I6: 4 | J6: 2003.92 | K6: 0 | L6: 267.88
A7: ORD-1136 | B7: 2025-07-08 | C7: Sanjay Reddy | D7: South | E7: Technology | F7: Phones | G7: Phones Model 739 | H7: Consumer | I7: 11 | J7: 6111.93 | K7: 0.15 | L7: 1261.89
A8: ORD-1176 | B8: 2024-04-06 | C8: Aditya Joshi | D8: West | E8: Furniture | F8: Bookcases | G8: Bookcases Model 966 | H8: Consumer | I8: 6 | J8: 3415.68 | K8: 0.15 | L8: 924.65
A9: ORD-1090 | B9: 2024-05-04 | C9: Karan Malhotra | D9: North | E9: Technology | F9: Machines | G9: Machines Model 144 | H9: Corporate | I9: 10 | J9: 2390.4 | K9: 0.3 | L9: 472.97
A10: ORD-1082 | B10: 2024-08-13 | C10: Pooja Desai | D10: South | E10: Furniture | F10: Tables | G10: Tables Model 137 | H10: Corporate | I10: 11 | J10: 6247.34 | K10: 0.3 | L10: 1216.39
A11: ORD-1067 | B11: 2023-02-05 | C11: Sanjay Reddy | D11: South | E11: Furniture | F11: Furnishings | G11: Furnishings Model 413 | H11: Home Office | I11: 2 | J11: 374.26 | K11: 0.1 | L11: 86.75
A12: ORD-1059 | B12: 2024-06-08 | C12: Sanjay Reddy | D12: West | E12: Office Supplies | F12: Binders | G12: Binders Model 835 | H12: Home Office | I12: 6 | J12: 678.96 | K12: 0.15 | L12: 195.71
A13: ORD-1062 | B13: 2023-05-22 | C13: Meera Pillai | D13: South | E13: Furniture | F13: Bookcases | G13: Bookcases Model 942 | H13: Home Office | I13: 9 | J13: 3544.29 | K13: 0 | L13: 1080.56
A14: ORD-1006 | B14: 2024-07-23 | D14: East | E14: Office Supplies | F14: Binders | G14: Binders Model 463 | H14: Consumer | I14: 8 | J14: 3095.04 | K14: 0 | L14: 305.78
A15: ORD-1002 | B15: 2024-03-23 | C15: Rohan Mehta | D15: East | E15: Furniture | F15: Furnishings | G15: Furnishings Model 833 | H15: Consumer | I15: 4 | J15: 1242.52 | K15: 0 | L15: 271.33
A16: ORD-1081 | B16: 2025-10-04 | C16: Divya Menon | D16: West | E16: Technology | F16: Machines | G16: Machines Model 786 | H16: Corporate | I16: 2 | J16: 579.92 | K16: 0.1 | L16: 78.29
A17: ORD-1046 | B17: 2024-02-12 | C17: Isha Kapoor | D17: North | E17: Office Supplies | F17: Binders | G17: Binders Model 725 | H17: Consumer | I17: 3 | J17: 87.87 | K17: 0 | L17: 30.33
A18: ORD-1001 | B18: 2024-04-02 | C18: Isha Kapoor | D18: North | E18: Technology | F18: Phones | G18: Phones Model 658 | H18: Consumer | I18: 3 | J18: 1337.52 | K18: 0.2 | L18: 291.26
A19: ORD-1058 | B19: 2024-05-21 | C19: Aarav Sharma | D19: East | E19: Furniture | F19: Chairs | G19: Chairs Model 229 | H19: Home Office | I19: 4 | J19: 2023.8 | K19: 0.15 | L19: 164.65
A20: ORD-1147 | B20: 2025-02-10 | C20: Vikram Rao | D20: North | E20: Technology | F20: Phones | G20: Phones Model 739 | H20: Home Office | I20: 3 | J20: 329.73 | K20: 0.3 | L20: 59.52
A21: ORD-1055 | B21: 2023-09-19 | C21: Sanjay Reddy | D21: West | E21: Technology | F21: Machines | G21: Machines Model 778 | H21: Home Office | I21: 10 | J21: 3274.6 | K21: 0.1 | L21: 670.67
A22: ORD-1113 | B22: 2024-05-28 | C22: Vikram Rao | D22: West | E22: Furniture | F22: Chairs | G22: Chairs Model 115 | H22: Corporate | I22: 3 | J22: 237.93 | K22: 0.3 | L22: 9.62
A23: ORD-1083 | B23: 2023-08-26 | C23: Aditya Joshi | D23: North | E23: Office Supplies | F23: Binders | G23: Binders Model 773 | H23: Corporate | I23: 7 | J23: 3646.79 | K23: 0.3 | L23: 884.36
A24: ORD-1029 | B24: 2024-03-12 | C24: Rohan Mehta | D24: East | E24: Furniture | F24: Chairs | G24: Chairs Model 350 | H24: Corporate | I24: 9 | J24: 1531.26 | K24: 0 | L24: 481.21
A25: ORD-1134 | B25: 2023-06-06 | C25: Ananya Gupta | D25: North | E25: Office Supplies | F25: Storage | G25: Storage Model 894 | H25: Consumer | I25: 9 | J25: 3468.96 | K25: 0.15 | L25: 598.53
A26: ORD-1052 | B26: 2024-11-08 | C26: Divya Menon | D26: South | E26: Furniture | F26: Tables | G26: Tables Model 530 | H26: Consumer | I26: 9 | J26: 2588.13 | K26: 0 | L26: 290
... A49: ORD-1045 | B49: 2023-12-14 | C49: Pooja Desai | D49: West | E49: Office Supplies | F49: Art | G49: Art Model 734 | H49: Corporate | I49: 11 | J49: 710.71 | K49: 0.15 | L49: 150.52
A50: ORD-1128 | B50: 2025-11-15 | C50: Karan Malhotra | D50: North | E50: Technology | F50: Machines | G50: Machines Model 794 | H50: Corporate | I50: 2 | K50: 0 | L50: 58.56
A51: ORD-1164 | B51: 2024-08-24 | C51: Ananya Gupta | D51: South | E51: Furniture | F51: Furnishings | G51: Furnishings Model 413 | H51: Consumer | I51: 6 | J51: 450.12 | K51: 0 | L51: 111.75
A52: ORD-1047 | B52: 2025-10-09 | C52: Rahul Bhat | D52: West | E52: Furniture | F52: Furnishings | G52: Furnishings Model 868 | H52: Corporate | I52: 7 | J52: 1104.11 | K52: 0.2 | L52: 226.37
A53: ORD-1180 | B53: 2023-05-03 | C53: Rohan Mehta | D53: South | E53: Furniture | F53: Furnishings | G53: Furnishings Model 448 | H53: Corporate | I53: 3 | J53: 816.51 | K53: 0.1 | L53: 139.13
A54: ORD-1023 | B54: 2024-04-29 | C54: Rohan Mehta | D54: East | E54: Technology | F54: Phones | G54: Phones Model 510 | H54: Consumer | I54: 3 | J54: 758.25 | K54: 0.1 | L54: 77.88
A55: ORD-1114 | B55: 2023-12-23 | C55: Aarav Sharma | D55: North | E55: Office Supplies | F55: Paper | G55: Paper Model 216 | H55: Home Office | I55: 5 | J55: 228.25 | K55: 0.2 | L55: 32.19
A56: ORD-1119 | B56: 2025-04-27 | C56: Isha Kapoor | D56: South | E56: Technology | F56: Accessories | G56: Accessories Model 197 | H56: Corporate | I56: 6 | J56: 2994.24 | K56: 0.1 | L56: 471.05
A57: ORD-1174 | B57: 2023-06-01 | C57: Divya Menon | D57: South | E57: Technology | F57: Machines | G57: Machines Model 577 | H57: Home Office | I57: 3 | J57: 1751.52 | K57: 0.2 | L57: 101.24
A58: ORD-1115 | B58: 2025-11-17 | C58: Meera Pillai | D58: South | E58: Technology | F58: Phones | G58: Phones Model 729 | H58: Corporate | I58: 10 | J58: 788 | K58: 0.15 | L58: 78.01
A59: ORD-1140 | B59: 2023-03-22 | C59: Ananya Gupta | D59: East | E59: Office Supplies | F59: Binders | G59: Binders Model 724 | H59: Corporate | I59: 4 | J59: 1715.84 | K59: 0.1 | L59: 320
A60: ORD-1088 | B60: 2024-07-19 | C60: Rohan Mehta | D60: West | E60: Office Supplies | F60: Paper | G60: Paper Model 940 | H60: Home Office | I60: 7 | J60: 1496.81 | K60: 0.3 | L60: 211.99
A61: ORD-1097 | B61: 2025-10-16 | C61: Isha Kapoor | D61: South | E61: Furniture | F61: Tables | G61: Tables Model 570 | H61: Consumer | I61: 10 | J61: 987.2 | K61: 0.1 | L61: 214.45
A62: ORD-1125 | B62: 2023-10-18 | C62: Rohan Mehta | D62: South | E62: Furniture | F62: Tables | G62: Tables Model 643 | H62: Consumer | I62: 12 | J62: 4624.92 | K62: 0 | L62: 358.56
... A70: ORD-1132 | B70: 2024-08-15 | C70: Divya Menon | D70: South | E70: Office Supplies | F70: Labels | G70: Labels Model 732 | H70: Corporate | I70: 2 | J70: 503.88 | K70: 0 | L70: 51.18
...

Sheet Cleaned_Data
A1: CLEANED DATA — Task 1: duplicates removed, missing values handled
A2: Task 4: conditional formatting highlights the TOP 10 highest values in the Sales column (red fill).
A3: Order ID | B3: Order Date | C3: Customer Name | D3: Region | E3: Category | F3: Sub-Category | G3: Product Name | H3: Department | I3: Quantity | J3: Sales | K3: Discount | L3: Profit | M3: Year | O3: Cleaning steps applied
A4: ORD-1001 | B4: 2024-04-02 | C4: Isha Kapoor | D4: North | E4: Technology | F4: Phones | G4: Phones Model 658 | H4: Consumer | I4: 3 | J4: 1337.52 | K4: 0.2 | L4: 291.26 | M4: 2024 | O4: 1. Removed 12 exact duplicate rows (drop_duplicates).
A5: ORD-1002 | B5: 2024-03-23 | C5: Rohan Mehta | D5: East | E5: Furniture | F5: Furnishings | G5: Furnishings Model 833 | H5: Consumer | I5: 4 | J5: 1242.52 | K5: 0 | L5: 271.33 | M5: 2024 | O5: 2. Blank "Customer Name" -> filled with "Unknown Customer".
A6: ORD-1003 | B6: 2023-01-14 | C6: Arjun Singh | D6: South | E6: Technology | F6: Machines | G6: Machines Model 320 | H6: Consumer | I6: 3 | J6: 1270.23 | K6: 0 | L6: 169.4 | M6: 2023 | O6: 3. Blank "Quantity" -> filled with the column median.
A7: ORD-1004 | B7: 2025-01-05 | C7: Sneha Iyer | D7: South | E7: Office Supplies | F7: Binders | G7: Binders Model 570 | H7: Consumer | I7: 6 | J7: 2209.08 | K7: 0.3 | L7: 97.47 | M7: 2025 | O7: 4. Blank "Sales" -> filled with the column median.
A8: ORD-1005 | B8: 2025-01-10 | C8: Neha Verma | D8: East | E8: Technology | F8: Phones | G8: Phones Model 333 | H8: Corporate | I8: 10 | J8: 1274.9 | K8: 0 | L8: 81.27 | M8: 2025 | O8: Result: 192 raw rows -> 180 cleaned rows.
A9: ORD-1006 | B9: 2024-07-23 | C9: Unknown Customer | D9: East | E9: Office Supplies | F9: Binders | G9: Binders Model 463 | H9: Consumer | I9: 8 | J9: 3095.04 | K9: 0 | L9: 305.78 | M9: 2024
A10: ORD-1007 | B10: 2025-12-29 | C10: Ananya Gupta | D10: East | E10: Furniture | F10: Bookcases | G10: Bookcases Model 755 | H10: Home Office | I10: 12 | J10: 1898.52 | K10: 0.1 | L10: 279.94 | M10: 2025
A11: ORD-1008 | B11: 2024-04-14 | C11: Priya Nair | D11: North | E11: Technology | F11: Accessories | G11: Accessories Model 316 | H11: Home Office | I11: 1 | J11: 485.95 | K11: 0.1 | L11: 57 | M11: 2024
A12: ORD-1009 | B12: 2025-07-28 | C12: Rahul Bhat | D12: South | E12: Technology | F12: Copiers | G12: Copiers Model 651 | H12: Consumer | I12: 3 | J12: 509.85 | K12: 0 | L12: 139.44 | M12: 2025
A13: ORD-1010 | B13: 2024-03-25 | C13: Meera Pillai | D13: South | E13: Office Supplies | F13: Labels | G13: Labels Model 981 | H13: Corporate | I13: 3 | J13: 939.21 | K13: 0 | L13: 259.91 | M13: 2024
A14: ORD-1011 | B14: 2023-05-11 | C14: Divya Menon | D14: West | E14: Furniture | F14: Tables | G14: Tables Model 666 | H14: Home Office | I14: 7 | J14: 1667.75 | K14: 0.1 | L14: 313.3 | M14: 2023
A15: ORD-1012 | B15: 2023-08-17 | C15: Aditya Joshi | D15: North | E15: Furniture | F15: Chairs | G15: Chairs Model 839 | H15: Home Office | I15: 5 | J15: 1346.7 | K15: 0.1 | L15: 61.78 | M15: 2023
A16: ORD-1013 | B16: 2024-09-03 | C16: Sneha Iyer | D16: West | E16: Technology | F16: Copiers | G16: Copiers Model 880 | H16: Home Office | I16: 11 | J16: 3431.78 | K16: 0 | L16: 328.94 | M16: 2024
A17: ORD-1014 | B17: 2023-02-09 | C17: Pooja Desai | D17: North | E17: Furniture | F17: Chairs | G17: Chairs Model 345 | H17: Home Office | I17: 2 | J17: 1117.04 | K17: 0.3 | L17: 228.35 | M17: 2023
A18: ORD-1015 | B18: 2025-09-22 | C18: Rohan Mehta | D18: East | E18: Furniture | F18: Tables | G18: Tables Model 231 | H18: Home Office | I18: 2 | J18: 1174.24 | K18: 0.15 | L18: 279.22 | M18: 2025
A19: ORD-1016 | B19: 2025-12-16 | C19: Arjun Singh | D19: West | E19: Technology | F19: Machines | G19: Machines Model 873 | H19: Home Office | I19: 10 | J19: 2625.4 | K19: 0 | L19: 862.9 | M19: 2025
A20: ORD-1017 | B20: 2025-02-03 | C20: Rahul Bhat | D20: North | E20: Technology | F20: Accessories | G20: Accessories Model 330 | H20: Home Office | I20: 8 | J20: 4330.16 | K20: 0.1 | L20: 336.33 | M20: 2025
... A183: ORD-1180 | B183: 2023-05-03 | C183: Rohan Mehta | D183: South | E183: Furniture | F183: Furnishings | G183: Furnishings Model 448 | H183: Corporate | I183: 3 | J183: 816.51 | K183: 0.1 | L183: 139.13 | M183: 2023

Sheet Analysis
A1: ANALYSIS — Pivot-style Summaries & Descriptive Statistics
A3: Task 2: Pivot Table — Region-wise Sales
A4: Region | B4: Total Sales
A5: East | B5: =SUMIF(Cleaned_Data!$D$4:$D$183,A5,Cleaned_Data!$J$4:$J$183) -> 56137.42
A6: West | B6: =SUMIF(Cleaned_Data!$D$4:$D$183,A6,Cleaned_Data!$J$4:$J$183) -> 70673.32
A7: North | B7: =SUMIF(Cleaned_Data!$D$4:$D$183,A7,Cleaned_Data!$J$4:$J$183) -> 110459.44
A8: South | B8: =SUMIF(Cleaned_Data!$D$4:$D$183,A8,Cleaned_Data!$J$4:$J$183) -> 124852.41
A9: Grand Total | B9: =SUM(B5:B8) -> 362122.59
A11: Task 3: Descriptive Statistics (Excel formulas)
A12: Metric | B12: Sales | C12: Quantity
A13: Mean | B13: =AVERAGE(Cleaned_Data!$J$4:$J$183) -> 2011.7922 | C13: =AVERAGE(Cleaned_Data!$I$4:$I$183) -> 6.6
A14: Median | B14: =MEDIAN(Cleaned_Data!$J$4:$J$183) -> 1454.96 | C14: =MEDIAN(Cleaned_Data!$I$4:$I$183) -> 7
A15: Mode | B15: =MODE(Cleaned_Data!$J$4:$J$183) -> 1454.96 | C15: =MODE(Cleaned_Data!$I$4:$I$183) -> 7
A18: Task 5: Category-wise Revenue (source data for bar chart)
A19: Category | B19: Revenue
A20: Furniture | B20: =SUMIF(Cleaned_Data!$E$4:$E$183,A20,Cleaned_Data!$J$4:$J$183) -> 150849.74
A21: Office Supplies | B21: =SUMIF(Cleaned_Data!$E$4:$E$183,A21,Cleaned_Data!$J$4:$J$183) -> 109018.16
A22: Technology | B22: =SUMIF(Cleaned_Data!$E$4:$E$183,A22,Cleaned_Data!$J$4:$J$183) -> 102254.69
A24: Project: Total Revenue
A25: Total Revenue | B25: =SUM(Cleaned_Data!$J$4:$J$183) -> 362122.59
A26: Total Profit | B26: =SUM(Cleaned_Data!$L$4:$L$183) -> 63640.54
A27: Total Orders | B27: =COUNTA(Cleaned_Data!$J$4:$J$183) -> 180
A29: Project: Yearly Sales Trends
A30: Year | B30: Total Sales
A31: 2023 | B31: =SUMIF(Cleaned_Data!$M$4:$M$183,A31,Cleaned_Data!$J$4:$J$183) -> 129909.33
A32: 2024 | B32: =SUMIF(Cleaned_Data!$M$4:$M$183,A32,Cleaned_Data!$J$4:$J$183) -> 126611.87
A33: 2025 | B33: =SUMIF(Cleaned_Data!$M$4:$M$183,A33,Cleaned_Data!$J$4:$J$183) -> 105601.39
A35: Project: Department-wise Revenue
A36: Department | B36: Revenue
A37: Consumer | B37: =SUMIF(Cleaned_Data!$H$4:$H$183,A37,Cleaned_Data!$J$4:$J$183) -> 125133.22
A38: Corporate | B38: =SUMIF(Cleaned_Data!$H$4:$H$183,A38,Cleaned_Data!$J$4:$J$183) -> 122763.72
A39: Home Office | B39: =SUMIF(Cleaned_Data!$H$4:$H$183,A39,Cleaned_Data!$J$4:$J$183) -> 114225.65

Sheet Charts
A1: CHARTS — Task 5 (Category Revenue) + Project Visuals
